Workbook

Sheet README
A1: Celebrity Gallery - Data Collection Guide
A3: PURPOSE
B4: This workbook is the source of truth for building the celebrity face gallery used by the face-forensics module (open-set identification: card-face embedding vs gallery via ArcFace/InsightFace cosine similarity).
B5: Each row in the 'Celebrities' sheet corresponds to exactly one gallery identity. The celeb_id column is the canonical key: use it as the .npz filename / FAISS label. Never rename a celeb_id after embeddings are built.
A7: WORKFLOW
B8: 1. Pick a country/tier slice (start with tier A of each P1 market).
B9: 2. For each celeb: verify identity against wiki_url/anchor URL, collect 10+ images per the rules below.
B10: 3. Run face crop + frontalization modules, update images_collected / images_frontal_ok.
B11: 4. Embed and add to gallery, set embedded_in_gallery = Y, then QC (self-match and impostor spot-check), set qc_status.
A13: IMAGE COLLECTION RULES
B14: - 10+ images per identity; after your crop/frontal pipeline, keep the best 10.
B15: - Face must be near-frontal (within ~±25° yaw), eyes visible, no sunglasses, minimal occlusion.
B16: - Min face size ~112x112 px AFTER crop (ArcFace input); prefer source images where the face is much larger.
B17: - Span variation: different ages/years, hairstyles, lighting, with/without beard or hijab styles where applicable.
B18: - Avoid: heavy stage makeup, movie prosthetics, filters, group photos where identity is ambiguous, waxworks, fan art, AI-generated images.
B19: - One identity per row - verify each downloaded image is really that person (search engines mix up lookalikes and relatives).
A21: THRESHOLD / QC TIPS
B22: - Keep a held-out probe set (2-3 images per celeb NOT in the gallery) to measure true-accept rate.
B23: - Build a hard-negative set: lookalike_of pairs, siblings, same-ethnicity non-celebs - use it to set the cosine threshold.
B24: - Track per-market thresholds if score distributions differ (they often do across ethnicities/datasets).
A26: COLUMN DEFINITIONS (Celebrities sheet)
A27: celeb_id | B27: Canonical key: <iso2>_<snake_case_name>. Used as gallery/.npz key. Immutable.
A28: full_name | B28: Common public name (romanized).
A29: aliases | B29: Stage names, nicknames, native-script spellings - improves web search recall.
A30: gender | B30: M/F, optional; blank if not applicable/preferred.
A31: birth_year | B31: Approximate is fine; helps plan age variation in samples. Blank = unverified.
A32: country_origin | B32: Nationality/origin country of the celebrity.
A33: target_market | B33: Where recognition matters for the product: GCC, PH, or GLOBAL.
A34: category / sub_category | B34: Coarse type (dropdown) and free-text specialization.
A35: tier | B35: A = instantly recognizable in market; B = well known; C = niche. Collect A first.
A36: lookalike_of | B36: celeb_id of a known lookalike/sibling in this sheet - used for hard-negative threshold tuning.
A37: deceased | B37: Y if deceased - their images still circulate and can appear on fraudulent cards.
A38: wiki_url | B38: Anchor URL to disambiguate identity before collecting (fill in during collection).
... A42: collector / notes | B42: Who collected; anything unusual.

Sheet Countries
A1: country | B1: iso2 | C1: role | D1: priority | E1: target_count | F1: seeded_in_sheet | G1: embedded_in_gallery | H1: status | I1: notes
A2: Saudi Arabia | B2: SA | C2: Primary market | D2: P1 | E2: 120 | F2: =COUNTIF(Celebrities!F:F,A2) | G2: =COUNTIFS(Celebrities!F:F,A2,Celebrities!P:P,"Y") | H2: Not started | I2: Domestic + pan-Arab + Saudi Pro League imports
A3: UAE | B3: AE | C3: Primary market | D3: P1 | E3: 100 | F3: =COUNTIF(Celebrities!F:F,A3) | G3: =COUNTIFS(Celebrities!F:F,A3,Celebrities!P:P,"Y") | H3: Not started | I3: Domestic + pan-Arab; large expat base - consider India/PK/PH lists too
A4: Qatar | B4: QA | C4: Primary market | D4: P1 | E4: 60 | F4: =COUNTIF(Celebrities!F:F,A4) | G4: =COUNTIFS(Celebrities!F:F,A4,Celebrities!P:P,"Y") | H4: Not started | I4: Domestic + pan-Arab
A5: Kuwait | B5: KW | C5: Primary market | D5: P1 | E5: 80 | F5: =COUNTIF(Celebrities!F:F,A5) | G5: =COUNTIFS(Celebrities!F:F,A5,Celebrities!P:P,"Y") | H5: Not started | I5: Strong domestic drama/comedy scene
A6: Bahrain | B6: BH | C6: Primary market | D6: P1 | E6: 40 | F6: =COUNTIF(Celebrities!F:F,A6) | G6: =COUNTIFS(Celebrities!F:F,A6,Celebrities!P:P,"Y") | H6: Not started | I6: Small domestic pool; leans on pan-Arab
A7: Oman | B7: OM | C7: Primary market | D7: P1 | E7: 40 | F7: =COUNTIF(Celebrities!F:F,A7) | G7: =COUNTIFS(Celebrities!F:F,A7,Celebrities!P:P,"Y") | H7: Not started | I7: Small domestic pool; leans on pan-Arab
A8: Philippines | B8: PH | C8: Primary market | D8: P1 | E8: 500 | F8: =COUNTIF(Celebrities!F:F,A8) | G8: =COUNTIFS(Celebrities!F:F,A8,Celebrities!P:P,"Y") | H8: Not started | I8: Deep domestic pool: showbiz, P-pop, basketball, beauty queens, vloggers
A9: Egypt | B9: EG | C9: Pan-Arab source | D9: P1-support | E9: 120 | F9: =COUNTIF(Celebrities!F:F,A9) | G9: =COUNTIFS(Celebrities!F:F,A9,Celebrities!P:P,"Y") | H9: Not started | I9: Film/music stars with massive GCC recognition
A10: Lebanon | B10: LB | C10: Pan-Arab source | D10: P1-support | E10: 80 | F10: =COUNTIF(Celebrities!F:F,A10) | G10: =COUNTIFS(Celebrities!F:F,A10,Celebrities!P:P,"Y") | H10: Not started | I10: Pop stars and drama actors watched across GCC
A11: Iraq | B11: IQ | C11: Pan-Arab source | D11: P1-support | E11: 30 | F11: =COUNTIF(Celebrities!F:F,A11) | G11: =COUNTIFS(Celebrities!F:F,A11,Celebrities!P:P,"Y") | H11: Not started
A12: Syria | B12: SY | C12: Pan-Arab source | D12: P1-support | E12: 30 | F12: =COUNTIF(Celebrities!F:F,A12) | G12: =COUNTIFS(Celebrities!F:F,A12,Celebrities!P:P,"Y") | H12: Not started | I12: Ramadan-drama actors widely known in GCC
A13: Morocco | B13: MA | C13: Pan-Arab source | D13: P2 | E13: 25 | F13: =COUNTIF(Celebrities!F:F,A13) | G13: =COUNTIFS(Celebrities!F:F,A13,Celebrities!P:P,"Y") | H13: Not started
A14: Algeria | B14: DZ | C14: Pan-Arab source | D14: P2 | E14: 20 | F14: =COUNTIF(Celebrities!F:F,A14) | G14: =COUNTIFS(Celebrities!F:F,A14,Celebrities!P:P,"Y") | H14: Not started
A15: Tunisia | B15: TN | C15: Pan-Arab source | D15: P2 | E15: 20 | F15: =COUNTIF(Celebrities!F:F,A15) | G15: =COUNTIFS(Celebrities!F:F,A15,Celebrities!P:P,"Y") | H15: Not started
A16: Jordan | B16: JO | C16: Pan-Arab source | D16: P2 | E16: 15 | F16: =COUNTIF(Celebrities!F:F,A16) | G16: =COUNTIFS(Celebrities!F:F,A16,Celebrities!P:P,"Y") | H16: Not started
A17: Palestine | B17: PS | C17: Pan-Arab source | D17: P2 | E17: 10 | F17: =COUNTIF(Celebrities!F:F,A17) | G17: =COUNTIFS(Celebrities!F:F,A17,Celebrities!P:P,"Y") | H17: Not started
A18: Global | B18: - | C18: High-visibility imports | D18: P1-support | E18: 50 | F18: =COUNTIF(Celebrities!G:G,"GLOBAL") | G18: =COUNTIFS(Celebrities!G:G,"GLOBAL",Celebrities!P:P,"Y") | H18: Not started | I18: Footballers in Saudi league, Hollywood A-list, global musicians

Sheet Celebrities
A1: celeb_id | B1: full_name | C1: aliases | D1: gender | E1: birth_year | F1: country_origin | G1: target_market | H1: category | I1: sub_category | J1: tier | K1: lookalike_of | L1: deceased | M1: wiki_url | N1: images_collected | O1: images_frontal_ok | P1: embedded_in_gallery | Q1: qc_status | R1: collector | S1: notes
A2: sa_mohammed_bin_salman | B2: Mohammed bin Salman | C2: MBS | D2: M | E2: 1985 | F2: Saudi Arabia | G2: GCC | H2: Politician/Royal | I2: Crown Prince | J2: A | L2: N | N2: 0 | O2: 0 | P2: N | Q2: Pending
A3: sa_salman_bin_abdulaziz_al_saud | B3: Salman bin Abdulaziz Al Saud | C3: King Salman | D3: M | E3: 1935 | F3: Saudi Arabia | G3: GCC | H3: Politician/Royal | I3: King | J3: A | L3: N | N3: 0 | O3: 0 | P3: N | Q3: Pending
A4: sa_turki_alalshikh | B4: Turki Alalshikh | C4: Turki Al-Sheikh | D4: M | E4: 1981 | F4: Saudi Arabia | G4: GCC | H4: Politician/Royal | I4: GEA Chairman | J4: A | L4: N | N4: 0 | O4: 0 | P4: N | Q4: Pending | S4: Very high media presence (Riyadh Season)
A5: sa_salem_al_dawsari | B5: Salem Al-Dawsari | D5: M | E5: 1991 | F5: Saudi Arabia | G5: GCC | H5: Sports | I5: Football | J5: A | L5: N | N5: 0 | O5: 0 | P5: N | Q5: Pending | S5: Scored winner vs Argentina WC2022
A6: sa_yasser_al_shahrani | B6: Yasser Al-Shahrani | D6: M | E6: 1992 | F6: Saudi Arabia | G6: GCC | H6: Sports | I6: Football | J6: B | L6: N | N6: 0 | O6: 0 | P6: N | Q6: Pending
A7: sa_salman_al_faraj | B7: Salman Al-Faraj | D7: M | E7: 1989 | F7: Saudi Arabia | G7: GCC | H7: Sports | I7: Football | J7: B | L7: N | N7: 0 | O7: 0 | P7: N | Q7: Pending
A8: sa_mohammed_al_owais | B8: Mohammed Al-Owais | D8: M | E8: 1991 | F8: Saudi Arabia | G8: GCC | H8: Sports | I8: Football (GK) | J8: B | L8: N | N8: 0 | O8: 0 | P8: N | Q8: Pending
A9: sa_firas_al_buraikan | B9: Firas Al-Buraikan | D9: M | E9: 2000 | F9: Saudi Arabia | G9: GCC | H9: Sports | I9: Football | J9: B | L9: N | N9: 0 | O9: 0 | P9: N | Q9: Pending
A10: sa_sami_al_jaber | B10: Sami Al-Jaber | D10: M | E10: 1972 | F10: Saudi Arabia | G10: GCC | H10: Sports | I10: Football (legend) | J10: A | L10: N | N10: 0 | O10: 0 | P10: N | Q10: Pending
A11: sa_yasser_al_qahtani | B11: Yasser Al-Qahtani | C11: The Sniper | D11: M | E11: 1982 | F11: Saudi Arabia | G11: GCC | H11: Sports | I11: Football (legend) | J11: A | L11: N | N11: 0 | O11: 0 | P11: N | Q11: Pending
A12: sa_nasser_al_qasabi | B12: Nasser Al-Qasabi | C12: Nasser Alqasabi | D12: M | E12: 1961 | F12: Saudi Arabia | G12: GCC | H12: Actor | I12: Comedy (Tash ma Tash) | J12: A | L12: N | N12: 0 | O12: 0 | P12: N | Q12: Pending
A13: sa_abdullah_al_sadhan | B13: Abdullah Al-Sadhan | D13: M | F13: Saudi Arabia | G13: GCC | H13: Actor | I13: Comedy (Tash ma Tash) | J13: B | L13: N | N13: 0 | O13: 0 | P13: N | Q13: Pending
A14: sa_fayez_al_malki | B14: Fayez Al-Malki | D14: M | F14: Saudi Arabia | G14: GCC | H14: Actor | I14: Comedy | J14: B | L14: N | N14: 0 | O14: 0 | P14: N | Q14: Pending
A15: sa_mohammed_abdu | B15: Mohammed Abdu | C15: Artist of the Arabs | D15: M | E15: 1949 | F15: Saudi Arabia | G15: GCC | H15: Singer/Musician | I15: Khaleeji | J15: A | L15: N | N15: 0 | O15: 0 | P15: N | Q15: Pending
A16: sa_abdul_majeed_abdullah | B16: Abdul Majeed Abdullah | C16: Abdul Majeed Abdallah | D16: M | E16: 1962 | F16: Saudi Arabia | G16: GCC | H16: Singer/Musician | I16: Khaleeji | J16: A | L16: N | N16: 0 | O16: 0 | P16: N | Q16: Pending
A17: sa_rabeh_saqer | B17: Rabeh Saqer | C17: Rabeh Sager | D17: M | F17: Saudi Arabia | G17: GCC | H17: Singer/Musician | I17: Khaleeji | J17: B | L17: N | N17: 0 | O17: 0 | P17: N | Q17: Pending
A18: sa_rashed_al_majed | B18: Rashed Al-Majed | C18: Rashed Al Majid | D18: M | E18: 1969 | F18: Saudi Arabia | G18: GCC | H18: Singer/Musician | I18: Khaleeji | J18: A | L18: N | N18: 0 | O18: 0 | P18: N | Q18: Pending | S18: Saudi-Bahraini
A19: sa_aseel_omran | B19: Aseel Omran | D19: F | E19: 1989 | F19: Saudi Arabia | G19: GCC | H19: Actor | I19: Actress/Singer | J19: B | L19: N | N19: 0 | O19: 0 | P19: N | Q19: Pending
A20: sa_mila_al_zahrani | B20: Mila Al Zahrani | D20: F | F20: Saudi Arabia | G20: GCC | H20: Actor | I20: Film | J20: B | L20: N | N20: 0 | O20: 0 | P20: N | Q20: Pending | S20: The Perfect Candidate
A21: sa_ahmad_al_shugairi | B21: Ahmad Al Shugairi | C21: Ahmed Alshugairi | D21: M | E21: 1973 | F21: Saudi Arabia | G21: GCC | H21: TV Host/Media | I21: Khawatir presenter | J21: A | L21: N | N21: 0 | O21: 0 | P21: N | Q21: Pending
A22: sa_lojain_omran | B22: Lojain Omran | D22: F | E22: 1977 | F22: Saudi Arabia | G22: GCC | H22: TV Host/Media | I22: Presenter/Influencer | J22: B | L22: N | N22: 0 | O22: 0 | P22: N | Q22: Pending
A23: sa_model_roz | B23: Model Roz | C23: Rose Al Otaibi | D23: F | F23: Saudi Arabia | G23: GCC | H23: Influencer | I23: Fashion | J23: B | L23: N | N23: 0 | O23: 0 | P23: N | Q23: Pending
A24: ae_mohamed_bin_zayed_al_nahyan | B24: Mohamed bin Zayed Al Nahyan | C24: MBZ | D24: M | E24: 1961 | F24: UAE | G24: GCC | H24: Politician/Royal | I24: President | J24: A | L24: N | N24: 0 | O24: 0 | P24: N | Q24: Pending
A25: ae_mohammed_bin_rashid_al_maktoum | B25: Mohammed bin Rashid Al Maktoum | C25: Sheikh Mohammed | D25: M | E25: 1949 | F25: UAE | G25: GCC | H25: Politician/Royal | I25: Ruler of Dubai / PM | J25: A | L25: N | N25: 0 | O25: 0 | P25: N | Q25: Pending
A26: ae_hamdan_bin_mohammed_al_maktoum | B26: Hamdan bin Mohammed Al Maktoum | C26: Fazza | D26: M | E26: 1982 | F26: UAE | G26: GCC | H26: Politician/Royal | I26: Crown Prince of Dubai | J26: A | L26: N | N26: 0 | O26: 0 | P26: N | Q26: Pending | S26: Huge Instagram following
A27: ae_hussain_al_jassmi | B27: Hussain Al Jassmi | C27: Hussain Al Jasmi | D27: M | E27: 1979 | F27: UAE | G27: GCC | H27: Singer/Musician | I27: Khaleeji/Pan-Arab | J27: A | L27: N | N27: 0 | O27: 0 | P27: N | Q27: Pending
A28: ae_ahlam_alshamsi | B28: Ahlam Alshamsi | C28: Ahlam | D28: F | E28: 1969 | F28: UAE | G28: GCC | H28: Singer/Musician | I28: Khaleeji / Arab Idol judge | J28: A | L28: N | N28: 0 | O28: 0 | P28: N | Q28: Pending
A29: ae_balqees_fathi | B29: Balqees Fathi | C29: Balqees | D29: F | E29: 1988 | F29: UAE | G29: GCC | H29: Singer/Musician | I29: Khaleeji | J29: A | L29: N | N29: 0 | O29: 0 | P29: N | Q29: Pending | S29: Yemeni-Emirati
A30: ae_ali_mabkhout | B30: Ali Mabkhout | D30: M | E30: 1990 | F30: UAE | G30: GCC | H30: Sports | I30: Football | J30: A | L30: N | N30: 0 | O30: 0 | P30: N | Q30: Pending
A31: ae_omar_abdulrahman | B31: Omar Abdulrahman | C31: Amoory | D31: M | E31: 1991 | F31: UAE | G31: GCC | H31: Sports | I31: Football | J31: A | L31: N | N31: 0 | O31: 0 | P31: N | Q31: Pending
A32: ae_khalid_al_ameri | B32: Khalid Al Ameri | D32: M | E32: 1984 | F32: UAE | G32: GCC | H32: Influencer | I32: Family/social vlogs | J32: A | L32: N | N32: 0 | O32: 0 | P32: N | Q32: Pending
A33: ae_anas_bukhash | B33: Anas Bukhash | C33: ABtalks | D33: M | E33: 1985 | F33: UAE | G33: GCC | H33: TV Host/Media | I33: Interview show / entrepreneur | J33: B | L33: N | N33: 0 | O33: 0 | P33: N | Q33: Pending
A34: ae_taim_al_falasi | B34: Taim Al Falasi | D34: F | E34: 1994 | F34: UAE | G34: GCC | H34: Influencer | I34: Lifestyle | J34: B | L34: N | N34: 0 | O34: 0 | P34: N | Q34: Pending
A35: ae_mahira_abdel_aziz | B35: Mahira Abdel Aziz | D35: F | F35: UAE | G35: GCC | H35: TV Host/Media | I35: Presenter | J35: B | L35: N | N35: 0 | O35: 0 | P35: N | Q35: Pending
A36: ae_habib_ghuloom | B36: Habib Ghuloom | D36: M | F36: UAE | G36: GCC | H36: Actor | I36: Drama/theatre | J36: B | L36: N | N36: 0 | O36: 0 | P36: N | Q36: Pending
A37: qa_tamim_bin_hamad_al_thani | B37: Tamim bin Hamad Al Thani | C37: Emir Tamim | D37: M | E37: 1980 | F37: Qatar | G37: GCC | H37: Politician/Royal | I37: Emir | J37: A | L37: N | N37: 0 | O37: 0 | P37: N | Q37: Pending
A38: qa_moza_bint_nasser | B38: Moza bint Nasser | C38: Sheikha Moza | D38: F | E38: 1959 | F38: Qatar | G38: GCC | H38: Politician/Royal | I38: Royal | J38: A | L38: N | N38: 0 | O38: 0 | P38: N | Q38: Pending
A39: qa_hamad_bin_khalifa_al_thani | B39: Hamad bin Khalifa Al Thani | C39: Father Emir | D39: M | E39: 1952 | F39: Qatar | G39: GCC | H39: Politician/Royal | I39: Former Emir | J39: B | L39: N | N39: 0 | O39: 0 | P39: N | Q39: Pending
A40: qa_akram_afif | B40: Akram Afif | D40: M | E40: 1996 | F40: Qatar | G40: GCC | H40: Sports | I40: Football | J40: A | L40: N | N40: 0 | O40: 0 | P40: N | Q40: Pending | S40: Asian Cup MVP
...
